<?xml version="1.0"?>
<robot name="myArm6DOF">

  <!-- Base Link -->
  <link name="base_link">
    <visual>
      <geometry>
        <box size="0.3 0.3 0.1"/>
      </geometry>
      <material name="blue">
        <color rgba="0 0 1 1"/>
      </material>
    </visual>
    <collision>
      <geometry>
        <box size="0.3 0.3 0.1"/>
      </geometry>
    </collision>
  </link>

  <!-- Pivots and Links -->
  <!-- Repeat pivot-link pairs for each DOF -->

  <link name="pivot_1">
    <visual>
      <geometry>
        <sphere radius="0.05"/>
      </geometry>
      <material name="grey">
        <color rgba="0.6 0.6 0.6 1"/>
      </material>
      <origin xyz="0 0 0.02" rpy="0 0 0"/>
    </visual>
    <collision>
      <geometry>
        <sphere radius="0.05"/>
      </geometry>
      <origin xyz="0 0 0.02" rpy="0 0 0"/>
    </collision>
  </link>

  <link name="link_1">
    <visual>
      <geometry>
        <cylinder length="0.25" radius="0.04"/>
      </geometry>
      <material name="blue">
        <color rgba="0 0 1 1"/>
      </material>
      <origin xyz="0 0 0.125" rpy="0 0 0"/>
    </visual>
    <collision>
      <geometry>
        <cylinder length="0.25" radius="0.04"/>
      </geometry>
      <origin xyz="0 0 0.125" rpy="0 0 0"/>
    </collision>
  </link>

  <link name="pivot_2">
    <visual>
      <geometry>
        <sphere radius="0.05"/>
      </geometry>
      <material name="grey">
        <color rgba="0.6 0.6 0.6 1"/>
      </material>
      <origin xyz="0 0 0.02" rpy="0 0 0"/>
    </visual>
    <collision>
      <geometry>
        <sphere radius="0.05"/>
      </geometry>
      <origin xyz="0 0 0.02" rpy="0 0 0"/>
    </collision>
  </link>

  <link name="link_2">
    <visual>
      <geometry>
        <cylinder length="0.25" radius="0.04"/>
      </geometry>
      <material name="blue">
        <color rgba="0 0 1 1"/>
      </material>
      <origin xyz="0 0 0.125" rpy="0 0 0"/>
    </visual>
    <collision>
      <geometry>
        <cylinder length="0.25" radius="0.04"/>
      </geometry>
      <origin xyz="0 0 0.125" rpy="0 0 0"/>
    </collision>
  </link>

  <link name="pivot_3">
    <visual>
      <geometry>
        <sphere radius="0.05"/>
      </geometry>
      <material name="grey">
        <color rgba="0.6 0.6 0.6 1"/>
      </material>
      <origin xyz="0 0 0.02" rpy="0 0 0"/>
    </visual>
    <collision>
      <geometry>
        <sphere radius="0.05"/>
      </geometry>
      <origin xyz="0 0 0.02" rpy="0 0 0"/>
    </collision>
  </link>

  <link name="link_3">
    <visual>
      <geometry>
        <cylinder length="0.25" radius="0.04"/>
      </geometry>
      <material name="blue">
        <color rgba="0 0 1 1"/>
      </material>
      <origin xyz="0 0 0.125" rpy="0 0 0"/>
    </visual>
    <collision>
      <geometry>
        <cylinder length="0.25" radius="0.04"/>
      </geometry>
      <origin xyz="0 0 0.125" rpy="0 0 0"/>
    </collision>
  </link>

  <link name="pivot_4">
    <visual>
      <geometry>
        <sphere radius="0.05"/>
      </geometry>
      <material name="grey">
        <color rgba="0.6 0.6 0.6 1"/>
      </material>
      <origin xyz="0 0 0.02" rpy="0 0 0"/>
    </visual>
    <collision>
      <geometry>
        <sphere radius="0.05"/>
      </geometry>
      <origin xyz="0 0 0.02" rpy="0 0 0"/>
    </collision>
  </link>

  <link name="link_4">
    <visual>
      <geometry>
        <cylinder length="0.25" radius="0.04"/>
      </geometry>
      <material name="blue">
        <color rgba="0 0 1 1"/>
      </material>
      <origin xyz="0 0 0.125" rpy="0 0 0"/>
    </visual>
    <collision>
      <geometry>
        <cylinder length="0.25" radius="0.04"/>
      </geometry>
      <origin xyz="0 0 0.125" rpy="0 0 0"/>
    </collision>
  </link>

  <link name="pivot_5">
    <visual>
      <geometry>
        <sphere radius="0.05"/>
      </geometry>
      <material name="grey">
        <color rgba="0.6 0.6 0.6 1"/>
      </material>
      <origin xyz="0 0 0.02" rpy="0 0 0"/>
    </visual>
    <collision>
      <geometry>
        <sphere radius="0.05"/>
      </geometry>
      <origin xyz="0 0 0.02" rpy="0 0 0"/>
    </collision>
  </link>

  <link name="link_5">
    <visual>
      <geometry>
        <cylinder length="0.25" radius="0.04"/>
      </geometry>
      <material name="blue">
        <color rgba="0 0 1 1"/>
      </material>
      <origin xyz="0 0 0.125" rpy="0 0 0"/>
    </visual>
    <collision>
      <geometry>
        <cylinder length="0.25" radius="0.04"/>
      </geometry>
      <origin xyz="0 0 0.125" rpy="0 0 0"/>
    </collision>
  </link>

  <link name="pivot_6">
    <visual>
      <geometry>
        <sphere radius="0.05"/>
      </geometry>
      <material name="grey">
        <color rgba="0.6 0.6 0.6 1"/>
      </material>
      <origin xyz="0 0 0.02" rpy="0 0 0"/>
    </visual>
    <collision>
      <geometry>
        <sphere radius="0.05"/>
      </geometry>
      <origin xyz="0 0 0.02" rpy="0 0 0"/>
    </collision>
  </link>

  <link name="link_6">
    <visual>
      <geometry>
        <cylinder length="0.25" radius="0.04"/>
      </geometry>
      <material name="blue">
        <color rgba="0 0 1 1"/>
      </material>
      <origin xyz="0 0 0.125" rpy="0 0 0"/>
    </visual>
    <collision>
      <geometry>
        <cylinder length="0.25" radius="0.04"/>
      </geometry>
      <origin xyz="0 0 0.125" rpy="0 0 0"/>
    </collision>
  </link>

  <link name="link_7">
    <visual>
      <geometry>
        <cylinder length="0.05" radius="0.02"/>
      </geometry>
      <material name="blue">
        <color rgba="0 0 1 1"/>
      </material>
      <origin xyz="0 0 0.025" rpy="0 0 0"/>
    </visual>
    <collision>
      <geometry>
        <cylinder length="0.05" radius="0.02"/>
      </geometry>
      <origin xyz="0 0 0.025" rpy="0 0 0"/>
    </collision>
  </link>

  <link name="pivot_7">
    <visual>
      <geometry>
        <sphere radius="0.03"/>
      </geometry>
      <material name="red">
        <color rgba="1 0 0 1"/>
      </material>
      <origin xyz="0 0 0.03" rpy="0 0 0"/>
    </visual>
    <collision>
      <geometry>
        <sphere radius="0.03"/>
      </geometry>
      <origin xyz="0 0 0.03" rpy="0 0 0"/>
    </collision>
  </link>

  <!-- JOINTS -->
  <joint name="joint_1" type="revolute">
    <parent link="base_link"/>
    <child link="pivot_1"/>
    <origin xyz="0 0 0.05" rpy="0 0 0"/>
    <axis xyz="0 0 1"/>
    <limit lower="-3.14" upper="3.14" effort="5" velocity="1.0"/>
  </joint>

  <joint name="joint_2" type="fixed">
    <parent link="pivot_1"/>
    <child link="link_1"/>
  </joint>

  <joint name="joint_3" type="revolute">
    <parent link="link_1"/>
    <child link="pivot_2"/>
    <origin xyz="0 0 0.25" rpy="0 0 0"/>
    <axis xyz="0 1 0"/>
    <limit lower="-3.14" upper="3.14" effort="5" velocity="1.0"/>
  </joint>

  <joint name="joint_4" type="fixed">
    <parent link="pivot_2"/>
    <child link="link_2"/>
  </joint>

  <joint name="joint_5" type="revolute">
    <parent link="link_2"/>
    <child link="pivot_3"/>
    <origin xyz="0 0 0.25" rpy="0 0 0"/>
    <axis xyz="0 1 0"/>
    <limit lower="-3.14" upper="3.14" effort="5" velocity="1.0"/>
  </joint>

  <joint name="joint_6" type="fixed">
    <parent link="pivot_3"/>
    <child link="link_3"/>
  </joint>

  <joint name="joint_7" type="revolute">
    <parent link="link_3"/>
    <child link="pivot_4"/>
    <origin xyz="0 0 0.25" rpy="0 0 0"/>
    <axis xyz="1 0 0"/>
    <limit lower="-3.14" upper="3.14" effort="5" velocity="1.0"/>
  </joint>

  <joint name="joint_8" type="fixed">
    <parent link="pivot_4"/>
    <child link="link_4"/>
  </joint>

  <joint name="joint_9" type="revolute">
    <parent link="link_4"/>
    <child link="pivot_5"/>
    <origin xyz="0 0 0.25" rpy="0 0 0"/>
    <axis xyz="0 1 0"/>
    <limit lower="-3.14" upper="3.14" effort="5" velocity="1.0"/>
  </joint>

  <joint name="joint_10" type="fixed">
    <parent link="pivot_5"/>
    <child link="link_5"/>
  </joint>

  <joint name="joint_11" type="revolute">
    <parent link="link_5"/>
    <child link="pivot_6"/>
    <origin xyz="0 0 0.25" rpy="0 0 0"/>
    <axis xyz="1 0 0"/>
    <limit lower="-3.14" upper="3.14" effort="5" velocity="1.0"/>
  </joint>

  <joint name="joint_12" type="fixed">
    <parent link="pivot_6"/>
    <child link="link_6"/>
  </joint>

  <joint name="joint_13" type="revolute">
    <parent link="link_6"/>
    <child link="link_7"/>
    <origin xyz="0 0 0.25" rpy="0 0 0"/>
    <axis xyz="0 0 1"/>
    <limit lower="-3.14" upper="3.14" effort="5" velocity="1.0"/>
  </joint>

  <joint name="joint_14" type="fixed">
    <parent link="link_7"/>
    <child link="pivot_7"/>
    <origin xyz="0 0 0.05" rpy="0 0 0"/>
  </joint>

  <ros2_control name="MyArmHardware" type="system">
    <hardware>
      <plugin>mock_components/GenericSystem</plugin>
    </hardware>

    <joint name="joint_1">
      <command_interface name="position"/>
      <state_interface name="position"/>
      <state_interface name="velocity"/>
    </joint>
  
    <joint name="joint_3">
      <command_interface name="position"/>
      <state_interface name="position"/>
      <state_interface name="velocity"/>
    </joint>
  
    <joint name="joint_5">
      <command_interface name="position"/>
      <state_interface name="position"/>
      <state_interface name="velocity"/>
    </joint>
  
    <joint name="joint_7">
      <command_interface name="position"/>
      <state_interface name="position"/>
      <state_interface name="velocity"/>
    </joint>
 
    <joint name="joint_9">
      <command_interface name="position"/>
      <state_interface name="position"/>
      <state_interface name="velocity"/>
    </joint>
  
    <joint name="joint_11">
      <command_interface name="position"/>
      <state_interface name="position"/>
      <state_interface name="velocity"/>
    </joint>
  
    <joint name="joint_13">
      <command_interface name="position"/>
      <state_interface name="position"/>
      <state_interface name="velocity"/>
     </joint>
   </ros2_control>

</robot>
